2024-06-23 20:58:36,172 - celery_task.async_task - ERROR - 发送给隐私增强系统失败，Error:HTTPConnectionPool(host='10.10.55.25', port=8082): Max retries exceeded with url: /common/desensitization/eTPSS?Address=shopping_name2_phone2_time2&url=mysql%2Bpymysql%3A%2F%2Froot%3A784512%40localhost%3A3306%2Flocal_test&worker_id=97d83d9b-6707-45a4-a2fc-8fe9459561d0 (Caused by ConnectTimeoutError(<urllib3.connection.HTTPConnection object at 0x7f9aaf53b550>, 'Connection to 10.10.55.25 timed out. (connect timeout=None)'))
